Workbook

Sheet Read Me
A1: This file contains data presented in the manuscript "Photochemical Processing of Dissolved Organic Matter from a Major Arctic River at Contrasting Hydrograph Stages."
A2: The data are organized in separate sheets as indicated on the tabs below. Associated units are provided in parentheses, either on the tab name or within the data tables.
A3: Consistent cell coloring is used to represent the Spring freshet (green), Late summer (blue), and Under-ice (red) UV exposure experiments.
A4: A brief description of the data is provided below. For methodological details, please refer to the "Methods" section of the manuscript and the "Supporting Information."
A5: For questions, please contact: Kyle J. Turner, Email: kturner@ccny.cuny.edu
A7: Irradiance (mW (m^2)^-1 nm^-1) | B7: The UV irradiance spectrum for the three experiment years, corrected for bottle scattering effects and adjusted using the measured PAR at each bottle position
A8: UV exposure calculations | B8: Calculations made to estimate the cumulative UV exposure of the irradiated samples over the course of each experiment, taking into account the varying optical pathlength and measured CDOM absorption at each time point.
A9: aCDOM (m^-1) | B9: Measured spectral absorption by CDOM relative to DI water, with NIR null correction applied, from 240-700 nm, for each experiment time point.
A10: EEMs (RU) | B10: Measured fluorescence Excitation-Emission Matrices (EEMs), with pure water correction and inner filter correction applied and scattering regions removed.
A11: DOC (mg L^-1) | B11: Measured pre- and post-exposure dissolved organic carbon concentrations for each experiment.
A12: Lignin | B12: Measured pre- and post-exposure lignin parameters for each experiment.
A13: FT ICR-MS | B13: Measured pre- and post-exposure FT ICR-MS parameters (weight-averaged) for each experiment.

Sheet Irradiance (mW (m^2)^-1 nm^-1)
A1: Wavelength (nm) | B1: 2022 spectrum corrected for Teflon bottle transmission | C1: Corrected spectrum adjusted for 2023 PAR=10.39 | D1: Corrected spectrum adjusted for 2024 PAR=10.45
A2: 284 | B2: 0.85898095 | C2: =B2*(10.39/10.8) -> 0.82637149 | D2: =B2*(10.45/10.8) -> 0.8311436
A3: 285 | B3: 0.85892188 | C3: =B3*(10.39/10.8) -> 0.82631466 | D3: =B3*(10.45/10.8) -> 0.83108645
A4: 286 | B4: 0.89238679 | C4: =B4*(10.39/10.8) -> 0.85850914 | D4: =B4*(10.45/10.8) -> 0.86346685
A5: 287 | B5: 0.8502326 | C5: =B5*(10.39/10.8) -> 0.81795525 | D5: =B5*(10.45/10.8) -> 0.82267876
A6: 288 | B6: 0.93964985 | C6: =B6*(10.39/10.8) -> 0.90397796 | D6: =B6*(10.45/10.8) -> 0.90919824
A7: 289 | B7: 1.376352 | C7: =B7*(10.39/10.8) -> 1.3241016 | D7: =B7*(10.45/10.8) -> 1.331748
A8: 290 | B8: 0.98032935 | C8: =B8*(10.39/10.8) -> 0.94311315 | D8: =B8*(10.45/10.8) -> 0.94855942
A9: 291 | B9: 1.0872886 | C9: =B9*(10.39/10.8) -> 1.0460119 | D9: =B9*(10.45/10.8) -> 1.0520524
A10: 292 | B10: 1.2893112 | C10: =B10*(10.39/10.8) -> 1.2403651 | D10: =B10*(10.45/10.8) -> 1.247528
A11: 293 | B11: 1.533658 | C11: =B11*(10.39/10.8) -> 1.4754358 | D11: =B11*(10.45/10.8) -> 1.4839561
A12: 294 | B12: 1.8848322 | C12: =B12*(10.39/10.8) -> 1.8132784 | D12: =B12*(10.45/10.8) -> 1.8237496
A13: 295 | B13: 2.4965221 | C13: =B13*(10.39/10.8) -> 2.4017468 | D13: =B13*(10.45/10.8) -> 2.4156163
... A118: 400 | B118: 24.883493 | C118: =B118*(10.39/10.8) -> 23.938842 | D118: =B118*(10.45/10.8) -> 24.077083

Sheet UV exposure calculations
B1: 2022 (Late summer) | G1: 2023 (Spring freshet) | O1: 2024 (Under-ice)
C2: t0-t1 | D2: t1-t3 | E2: t3-t6 | F2: t6-t7 | H2: t0-t1 | I2: t1-t2 | J2: t2-t3 | K2: t3-t4 | L2: t4-t7 | M2: t7-t8 | N2: t8-t10 | P2: t0-t1 | Q2: t1-t2 | R2: t2-t4 | S2: t4-t5 | T2: t5-t6
A3: Volume (mL) | C3: 149.9 | D3: 142.9 | E3: 139.8 | F3: 133.75 | H3: 150 | I3: 144 | J3: 138 | K3: 132 | L3: 126 | M3: 120 | N3: 114 | P3: 150 | Q3: 144 | R3: 138 | S3: 132 | T3: 126
A4: Pathlength (m) | C4: =C3*(0.04/100) -> 0.05996 | D4: =D3*(0.04/100) -> 0.05716 | E4: =E3*(0.04/100) -> 0.05592 | F4: =F3*(0.04/100) -> 0.0535 | H4: =H3*(0.04/100) -> 0.06 | I4: =I3*(0.04/100) -> 0.0576 | J4: =J3*(0.04/100) -> 0.0552 | K4: =K3*(0.04/100) -> 0.0528 | L4: =L3*(0.04/100) -> 0.0504 | M4: =M3*(0.04/100) -> 0.048 | N4: =N3*(0.04/100) -> 0.0456 | P4: =P3*(0.04/100) -> 0.06 | Q4: =Q3*(0.04/100) -> 0.0576 | R4: =R3*(0.04/100) -> 0.0552 | S4: =S3*(0.04/100) -> 0.0528 | T4: =T3*(0.04/100) -> 0.0504
A5: Average UV (W/m2) | C5: {=0.001*SUMPRODUCT('Irradiance (mW (m^2)^-1 nm^-1)'!$B2:$B118,(1-EXP(-C4*(B9:B125*C9:C125)^0.5))/(C4*(B9:B125*C9:C125)^0.5))} -> 13.519441 | D5: {=0.001*SUMPRODUCT('Irradiance (mW (m^2)^-1 nm^-1)'!$B2:$B118,(1-EXP(-D4*(C9:C125*D9:D125)^0.5))/(D4*(C9:C125*D9:D125)^0.5))} -> 14.088496 | E5: {=0.001*SUMPRODUCT('Irradiance (mW (m^2)^-1 nm^-1)'!$B2:$B118,(1-EXP(-E4*(D9:D125*E9:E125)^0.5))/(E4*(D9:D125*E9:E125)^0.5))} -> 14.653136 | F5: {=0.001*SUMPRODUCT('Irradiance (mW (m^2)^-1 nm^-1)'!$B2:$B118,(1-EXP(-F4*(E9:E125*F9:F125)^0.5))/(F4*(E9:E125*F9:F125)^0.5))} -> 15.006611 | H5: {=0.001*SUMPRODUCT('Irradiance (mW (m^2)^-1 nm^-1)'!$C2:$C118,(1-EXP(-H4*(G9:G125*H9:H125)^0.5))/(H4*(G9:G125*H9:H125)^0.5))} -> 8.7754125 | I5: {=0.001*SUMPRODUCT('Irradiance (mW (m^2)^-1 nm^-1)'!$C2:$C118,(1-EXP(-I4*(H9:H125*I9:I125)^0.5))/(I4*(H9:H125*I9:I125)^0.5))} -> 9.4714502 | J5: {=0.001*SUMPRODUCT('Irradiance (mW (m^2)^-1 nm^-1)'!$C2:$C118,(1-EXP(-J4*(I9:I125*J9:J125)^0.5))/(J4*(I9:I125*J9:J125)^0.5))} -> 10.081885 | K5: {=0.001*SUMPRODUCT('Irradiance (mW (m^2)^-1 nm^-1)'!$C2:$C118,(1-EXP(-K4*(J9:J125*K9:K125)^0.5))/(K4*(J9:J125*K9:K125)^0.5))} -> 10.592205 | L5: {=0.001*SUMPRODUCT('Irradiance (mW (m^2)^-1 nm^-1)'!$C2:$C118,(1-EXP(-L4*(K9:K125*L9:L125)^0.5))/(L4*(K9:K125*L9:L125)^0.5))} -> 11.281777 | M5: {=0.001*SUMPRODUCT('Irradiance (mW (m^2)^-1 nm^-1)'!$C2:$C118,(1-EXP(-M4*(L9:L125*M9:M125)^0.5))/(M4*(L9:L125*M9:M125)^0.5))} -> 11.930492 | N5: {=0.001*SUMPRODUCT('Irradiance (mW (m^2)^-1 nm^-1)'!$C2:$C118,(1-EXP(-N4*(M9:M125*N9:N125)^0.5))/(N4*(M9:M125*N9:N125)^0.5))} -> 12.389918 | P5: {=0.001*SUMPRODUCT('Irradiance (mW (m^2)^-1 nm^-1)'!$D2:$D118,(1-EXP(-P4*(O9:O125*P9:P125)^0.5))/(P4*(O9:O125*P9:P125)^0.5))} -> 14.496699 | Q5: {=0.001*SUMPRODUCT('Irradiance (mW (m^2)^-1 nm^-1)'!$D2:$D118,(1-EXP(-Q4*(P9:P125*Q9:Q125)^0.5))/(Q4*(P9:P125*Q9:Q125)^0.5))} -> 14.69817 | R5: {=0.001*SUMPRODUCT('Irradiance (mW (m^2)^-1 nm^-1)'!$D2:$D118,(1-EXP(-R4*(Q9:Q125*R9:R125)^0.5))/(R4*(Q9:Q125*R9:R125)^0.5))} -> 14.861306 | S5: {=0.001*SUMPRODUCT('Irradiance (mW (m^2)^-1 nm^-1)'!$D2:$D118,(1-EXP(-S4*(R9:R125*S9:S125)^0.5))/(S4*(R9:R125*S9:S125)^0.5))} -> 14.985013 | T5: {=0.001*SUMPRODUCT('Irradiance (mW (m^2)^-1 nm^-1)'!$D2:$D118,(1-EXP(-T4*(S9:S125*T9:T125)^0.5))/(T4*(S9:S125*T9:T125)^0.5))} -> 15.055386
A6: Cumulative Exposure (MJ/m2) | B6: 0 | C6: =C5*0.0864+B6 -> 1.1680797 | D6: =D5*0.0864*2+C6 -> 3.6025718 | E6: =E5*0.0864*3+D6 -> 7.4006648 | F6: =F5*0.0864+E6 -> 8.697236 | G6: 0 | H6: =H5*0.0864+G6 -> 0.75819564 | I6: =I5*0.0864+H6 -> 1.5765289 | J6: =J5*0.0864+I6 -> 2.4476038 | K6: =K5*0.0864+J6 -> 3.3627703 | L6: =L5*0.0864*3+K6 -> 6.2870067 | M6: =M5*0.0864+L6 -> 7.3178013 | N6: =N5*0.0864*2+M6 -> 9.4587792 | O6: 0 | P6: =P5*0.0864+O6 -> 1.2525148 | Q6: =Q5*0.0864+P6 -> 2.5224366 | R6: =R5*0.0864*2+Q6 -> 5.0904703 | S6: =S5*0.0864+R6 -> 6.3851755 | T6: =T5*0.0864+S6 -> 7.6859608
A7: Average Absorption Spectra | B7: t0 | C7: t1 | D7: t3 | E7: t6 | F7: t7 | G7: t0 | H7: t1 | I7: t2 | J7: t3 | K7: t4 | L7: t7 | M7: t8 | N7: t10 | O7: t0 | P7: t1 | Q7: t2 | R7: t4 | S7: t5 | T7: t6
A8: Wavelength (nm) | B8: aCDOM (m-1)
A9: 284 | B9: 18.26803 | C9: 16.970672 | D9: 14.319036 | E9: 11.333546 | F9: 10.630102 | G9: 56.652885 | H9: 53.489117 | I9: 50.136537 | J9: 47.259095 | K9: 44.921615 | L9: 38.539332 | M9: 36.55022 | N9: 32.637132 | O9: 8.299692 | P9: 7.5363824 | Q9: 6.9370642 | R9: 6.208583 | S9: 5.8440539 | T9: 5.58612
A10: 285 | B10: 18.006805 | C10: 16.637321 | D10: 13.991901 | E10: 11.031568 | F10: 10.340408 | G10: 55.92078 | H10: 52.669262 | I10: 49.264299 | J10: 46.381287 | K10: 44.029987 | L10: 37.660204 | M10: 35.699025 | N10: 31.835018 | O10: 8.1354073 | P10: 7.3755462 | Q10: 6.7855541 | R10: 6.0362748 | S10: 5.6868513 | T10: 5.4159649
A11: 286 | B11: 17.697369 | C11: 16.296947 | D11: 13.643263 | E11: 10.71207 | F11: 9.9917569 | G11: 55.130656 | H11: 51.786953 | I11: 48.383939 | J11: 45.469803 | K11: 43.157179 | L11: 36.831617 | M11: 34.850394 | N11: 31.071628 | O11: 7.9914524 | P11: 7.2072237 | Q11: 6.5918192 | R11: 5.889494 | S11: 5.5263288 | T11: 5.2726338
A12: 287 | B12: 17.392727 | C12: 15.943401 | D12: 13.328331 | E12: 10.422767 | F12: 9.7180875 | G12: 54.330077 | H12: 50.929213 | I12: 47.527767 | J12: 44.630551 | K12: 42.263767 | L12: 35.95986 | M12: 34.030402 | N12: 30.268424 | O12: 7.8482999 | P12: 7.0190736 | Q12: 6.4313077 | R12: 5.6918251 | S12: 5.3527556 | T12: 5.1208626
A13: 288 | B13: 17.109525 | C13: 15.658145 | D13: 13.006321 | E13: 10.116868 | F13: 9.4390008 | G13: 53.576063 | H13: 50.086167 | I13: 46.663231 | J13: 43.735331 | K13: 41.389684 | L13: 35.142333 | M13: 33.216008 | N13: 29.513089 | O13: 7.7172125 | P13: 6.8568407 | Q13: 6.2584707 | R13: 5.5284903 | S13: 5.1851802 | T13: 4.9501015
A14: 289 | B14: 16.849694 | C14: 15.356369 | D14: 12.681559 | E14: 9.8181506 | F14: 9.1513952 | G14: 52.780854 | H14: 49.248383 | I14: 45.812989 | J14: 42.878891 | K14: 40.531018 | L14: 34.331968 | M14: 32.417475 | N14: 28.745537 | O14: 7.5313498 | P14: 6.7087785 | Q14: 6.108843 | R14: 5.4012627 | S14: 5.0471585 | T14: 4.8079676
A15: 290 | B15: 16.550464 | C15: 15.005593 | D15: 12.36147 | E15: 9.5225597 | F15: 8.8587536 | G15: 52.036245 | H15: 48.384104 | I15: 44.958788 | J15: 42.033313 | K15: 39.709383 | L15: 33.514503 | M15: 31.617718 | N15: 28.023852 | O15: 7.4162432 | P15: 6.5478826 | Q15: 5.9572762 | R15: 5.224792 | S15: 4.8881715 | T15: 4.659913
A16: 291 | B16: 16.272319 | C16: 14.700868 | D16: 12.08088 | E16: 9.2243067 | F16: 8.5771775 | G16: 51.284897 | H16: 47.599263 | I16: 44.095377 | J16: 41.19461 | K16: 38.885947 | L16: 32.731077 | M16: 30.862237 | N16: 27.298421 | O16: 7.2828249 | P16: 6.3993222 | Q16: 5.8032179 | R16: 5.0896182 | S16: 4.7560566 | T16: 4.5190882
A17: 292 | B17: 15.971217 | C17: 14.406312 | D17: 11.774075 | E17: 8.9854203 | F17: 8.3408391 | G17: 50.517743 | H17: 46.759189 | I17: 43.298952 | J17: 40.394774 | K17: 38.092641 | L17: 32.004779 | M17: 30.12404 | N17: 26.63313 | O17: 7.1380629 | P17: 6.2474709 | Q17: 5.684333 | R17: 4.9539564 | S17: 4.6008421 | T17: 4.3855201
A18: 293 | B18: 15.710679 | C18: 14.090718 | D18: 11.491017 | E18: 8.7016866 | F18: 8.0688519 | G18: 49.807952 | H18: 46.01119 | I18: 42.49598 | J18: 39.581993 | K18: 37.291199 | L18: 31.251889 | M18: 29.413923 | N18: 25.946669 | O18: 7.0165946 | P18: 6.0993806 | Q18: 5.5289767 | R18: 4.8088381 | S18: 4.4784589 | T18: 4.2691687
A19: 294 | B19: 15.458778 | C19: 13.821477 | D19: 11.197269 | E19: 8.4937812 | F19: 7.8382469 | G19: 49.046315 | H19: 45.164154 | I19: 41.726921 | J19: 38.797464 | K19: 36.527246 | L19: 30.54555 | M19: 28.701722 | N19: 25.337337 | O19: 6.8688722 | P19: 5.9781942 | Q19: 5.3735769 | R19: 4.6667228 | S19: 4.3478704 | T19: 4.1209169
A20: 295 | B20: 15.211555 | C20: 13.54242 | D20: 10.930734 | E20: 8.2281448 | F20: 7.6093298 | G20: 48.355607 | H20: 44.46057 | I20: 40.940052 | J20: 38.082025 | K20: 35.813004 | L20: 29.849382 | M20: 28.033259 | N20: 24.695821 | O20: 6.7408037 | P20: 5.8301892 | Q20: 5.2494597 | R20: 4.5589391 | S20: 4.2437611 | T20: 4.0151767
... A475: 750 | B475: -0.024668358 | C475: -0.036061483 | D475: -0.025957173 | E475: -0.026945705 | F475: -0.037939178 | G475: -0.070190736 | H475: -0.026564228 | I475: 0.0035817781 | J475: -0.019244807 | K475: 0.0023705256 | L475: -0.0015802542 | M475: 0.019931892 | N475: -0.0013584374 | O475: 0.038664118 | P475: 0.024102504 | Q475: 0.0049831231 | R475: -0.0096869226 | S475: -0.0043610615 | T475: 0.0091184427

Sheet aCDOM (m^-1)
A1: Wavelength (nm) | B1: Spring_freshet_t0 | C1: Spring_freshet_t1 | D1: Spring_freshet_t2 | E1: Spring_freshet_t3 | F1: Spring_freshet_t4 | G1: Spring_freshet_t7 | H1: Spring_freshet_t8 | I1: Spring_freshet_t10 | J1: Spring_freshet_t10_dark_control | K1: Late_summer_t0 | L1: Late_summer_t1 | M1: Late_summer_t3 | N1: Late_summer_t6 | O1: Late_summer_t7 | P1: Late_summer_t7_dark_control | Q1: Under_ice_t0 | R1: Under_ice_t1 | S1: Under_ice_t2 | T1: Under_ice_t4 | U1: Under_ice_t5 | V1: Under_ice_t6 | W1: Under_ice_t6_dark_control
A2: 240 | B2: 92.605363 | C2: 87.472327 | D2: 83.038888 | E2: 79.714694 | F2: 77.214783 | G2: 69.720155 | H2: 67.377409 | I2: 62.124164 | J2: 91.083973 | K2: 31.365795 | L2: 29.661692 | M2: 26.434209 | N2: 23.083274 | O2: 22.284074 | P2: 32.846806 | Q2: 13.237625 | R2: 13.775401 | S2: 13.016413 | T2: 12.125641 | U2: 11.675391 | V2: 11.390725 | W2: 15.769783
A3: 241 | B3: 91.456803 | C3: 86.44499 | D3: 82.077362 | E3: 78.840167 | F3: 76.338161 | G3: 68.963364 | H3: 66.640396 | I3: 61.434453 | J3: 89.995033 | K3: 30.927609 | L3: 29.299699 | M3: 26.089014 | N3: 22.78861 | O3: 21.979818 | P3: 32.434526 | Q3: 13.023757 | R3: 13.507631 | S3: 12.760716 | T3: 11.903068 | U3: 11.453523 | V3: 11.171883 | W3: 15.482703
A4: 242 | B4: 90.354024 | C4: 85.475557 | D4: 81.136718 | E4: 77.996707 | F4: 75.515637 | G4: 68.202466 | H4: 65.898826 | I4: 60.791401 | J4: 88.838099 | K4: 30.515466 | L4: 28.905582 | M4: 25.748847 | N4: 22.538525 | O4: 21.739455 | P4: 32.021017 | Q4: 12.840724 | R4: 13.271551 | S4: 12.537049 | T4: 11.658184 | U4: 11.236785 | V4: 10.9583 | W4: 15.210628
A5: 243 | B5: 89.301083 | C5: 84.515108 | D5: 80.324246 | E5: 77.19968 | F5: 74.807336 | G5: 67.585444 | H5: 65.274048 | I5: 60.24532 | J5: 87.891405 | K5: 30.123697 | L5: 28.553067 | M5: 25.46781 | N5: 22.261903 | O5: 21.477348 | P5: 31.614677 | Q5: 12.705803 | R5: 13.080311 | S5: 12.350592 | T5: 11.508302 | U5: 11.091082 | V5: 10.789339 | W5: 14.999029
A6: 244 | B6: 88.265314 | C6: 83.650539 | D6: 79.506173 | E6: 76.448628 | F6: 74.054397 | G6: 66.925341 | H6: 64.685036 | I6: 59.65613 | J6: 86.872891 | K6: 29.793362 | L6: 28.253082 | M6: 25.219397 | N6: 22.05939 | O6: 21.274807 | P6: 31.250235 | Q6: 12.579378 | R6: 12.896083 | S6: 12.191055 | T6: 11.35619 | U6: 10.92724 | V6: 10.656345 | W6: 14.80685
A7: 245 | B7: 87.289314 | C7: 82.798986 | D7: 78.730704 | E7: 75.762965 | F7: 73.417814 | G7: 66.395251 | H7: 64.143216 | I7: 59.188443 | J7: 85.949379 | K7: 29.458511 | L7: 27.975546 | M7: 24.99659 | N7: 21.869274 | O7: 21.086705 | P7: 30.899252 | Q7: 12.476172 | R7: 12.723823 | S7: 12.024727 | T7: 11.202157 | U7: 10.788781 | V7: 10.521193 | W7: 14.576628
A8: 246 | B8: 86.365639 | C8: 82.046775 | D8: 78.041711 | E8: 75.094923 | F8: 72.773698 | G8: 65.880199 | H8: 63.658115 | I8: 58.737306 | J8: 85.036571 | K8: 29.143378 | L8: 27.715999 | M8: 24.797615 | N8: 21.720589 | O8: 20.929845 | P8: 30.590767 | Q8: 12.361414 | R8: 12.588643 | S8: 11.89585 | T8: 11.090809 | U8: 10.677086 | V8: 10.407347 | W8: 14.417799
A9: 247 | B9: 85.496498 | C9: 81.313586 | D9: 77.395859 | E9: 74.485497 | F9: 72.248039 | G9: 65.420078 | H9: 63.190637 | I9: 58.327764 | J9: 84.19706 | K9: 28.84371 | L9: 27.480035 | M9: 24.586897 | N9: 21.54705 | O9: 20.777905 | P9: 30.297838 | Q9: 12.309939 | R9: 12.46989 | S9: 11.79842 | T9: 10.990531 | U9: 10.588556 | V9: 10.304367 | W9: 14.261837
A10: 248 | B10: 84.631116 | C10: 80.656948 | D10: 76.789056 | E10: 73.902732 | F10: 71.698801 | G10: 64.941418 | H10: 62.746319 | I10: 57.919408 | J10: 83.347821 | K10: 28.579242 | L10: 27.233091 | M10: 24.413404 | N10: 21.37641 | O10: 20.621907 | P10: 30.005223 | Q10: 12.200156 | R10: 12.348363 | S10: 11.669864 | T10: 10.87476 | U10: 10.472161 | V10: 10.217415 | W10: 14.118693
A11: 249 | B11: 83.793623 | C11: 79.901623 | D11: 76.170922 | E11: 73.390812 | F11: 71.219732 | G11: 64.551319 | H11: 62.372536 | I11: 57.564513 | J11: 82.573333 | K11: 28.283761 | L11: 27.006555 | M11: 24.264768 | N11: 21.256262 | O11: 20.503836 | P11: 29.721955 | Q11: 12.159472 | R11: 12.249087 | S11: 11.581266 | T11: 10.808275 | U11: 10.41227 | V11: 10.139042 | W11: 13.990552
A12: 250 | B12: 83.002906 | C12: 79.328223 | D12: 75.659952 | E12: 72.888086 | F12: 70.728449 | G12: 64.101593 | H12: 61.952614 | I12: 57.211205 | J12: 81.850772 | K12: 28.04034 | L12: 26.818508 | M12: 24.108332 | N12: 21.123918 | O12: 20.373185 | P12: 29.44143 | Q12: 12.085698 | R12: 12.159359 | S12: 11.502225 | T12: 10.724246 | U12: 10.337247 | V12: 10.05828 | W12: 13.860654
A13: 251 | B13: 82.238679 | C13: 78.661115 | D13: 75.102198 | E13: 72.390583 | F13: 70.252755 | G13: 63.69796 | H13: 61.571762 | I13: 56.855784 | J13: 81.125424 | K13: 27.800799 | L13: 26.617848 | M13: 23.93617 | N13: 20.955344 | O13: 20.226472 | P13: 29.191469 | Q13: 12.026005 | R13: 12.056032 | S13: 11.401823 | T13: 10.65925 | U13: 10.258326 | V13: 9.9902081 | W13: 13.744323
... A462: 700 | B462: 0.051910269 | C462: 0.046890992 | D462: 0.055040472 | E462: 0.022181652 | F462: 0.038961571 | G462: 0.058665607 | H462: 0.024779012 | I462: 0.04591685 | J462: 0.040933809 | K462: 0.016411291 | L462: 0.058405062 | M462: 0.047738688 | N462: 0.017941451 | O462: 0.023463037 | P462: 0.023669822 | Q462: 0.028832911 | R462: -0.0075396923 | S462: -0.014494701 | T462: 0.01091688 | U462: -0.012528165 | V462: 0.0029064646 | W462: -0.0049922243

Sheet EEMs (RU)
A1: Spring_freshet_t0
B2: Ex (nm) | C2: 250 | D2: 255 | E2: 260 | F2: 265 | G2: 270 | H2: 275 | I2: 280 | J2: 285 | K2: 290 | L2: 295 | M2: 300 | N2: 305 | O2: 310 | P2: 315 | Q2: 320 | R2: 325 | S2: 330 | T2: 335 | U2: 340 | V2: 345 | W2: 350 | X2: 355 | Y2: 360 | Z2: 365 | AA2: 370 | AB2: 375 | AC2: 380 | AD2: 385 | AE2: 390 | AF2: 395 | AG2: 400
A3: Em (nm)
A4: 300 | C4: 0.14458964 | D4: 0.17935707 | E4: 0.1993825 | F4: 0.23793257 | G4: NaN | H4: NaN | I4: 0.29118671 | J4: 0.20613424 | K4: NaN | L4: NaN | M4: NaN | N4: NaN | O4: NaN | P4: NaN | Q4: NaN | R4: NaN | S4: NaN | T4: NaN | U4: NaN | V4: 0.021683416 | W4: 0.0099883649 | X4: 0.010616923 | Y4: 0.0050300912 | Z4: 0.0081701371 | AA4: 0.002896425 | AB4: 0.0030033486 | AC4: 0.0018229587 | AD4: 0 | AE4: 0 | AF4: 9.2127214e-05 | AG4: 0.00061139442
A5: 302 | C5: 0.16925601 | D5: 0.19339129 | E5: 0.22471511 | F5: 0.26834719 | G5: NaN | H5: NaN | I5: 0.30569493 | J5: 0.2251791 | K5: 0.14300825 | L5: NaN | M5: NaN | N5: NaN | O5: NaN | P5: NaN | Q5: NaN | R5: NaN | S5: NaN | T5: NaN | U5: NaN | V5: NaN | W5: 0.015974893 | X5: 0.0087040782 | Y5: 0.0098365065 | Z5: 0.0058731503 | AA5: 0.0042365946 | AB5: 0.0026362213 | AC5: 0.0023863684 | AD5: 0.0029592643 | AE5: 0.00073121092 | AF5: 0 | AG5: 0
A6: 304 | C6: 0.19243973 | D6: 0.20833195 | E6: 0.22163319 | F6: 0.28683225 | G6: 0.31517387 | H6: NaN | I6: NaN | J6: 0.23983389 | K6: 0.16062396 | L6: NaN | M6: NaN | N6: NaN | O6: NaN | P6: NaN | Q6: NaN | R6: NaN | S6: NaN | T6: NaN | U6: NaN | V6: NaN | W6: 0.013683112 | X6: 0.011312085 | Y6: 0.010061088 | Z6: 0.006316333 | AA6: 0.0064015585 | AB6: 0.0037146824 | AC6: 0.0058164765 | AD6: 0.002815666 | AE6: 0 | AF6: 0.0004202723 | AG6: 0
A7: 306 | C7: 0.18981301 | D7: 0.19608278 | E7: 0.24198491 | F7: 0.29326614 | G7: 0.3213673 | H7: NaN | I7: NaN | J7: 0.25672263 | K7: 0.1765903 | L7: 0.11527957 | M7: NaN | N7: NaN | O7: NaN | P7: NaN | Q7: NaN | R7: NaN | S7: NaN | T7: NaN | U7: NaN | V7: NaN | W7: 0.021386132 | X7: 0.012527292 | Y7: 0.010343647 | Z7: 0.00676359 | AA7: 0.0091454002 | AB7: 0.0049238818 | AC7: 0.0065863721 | AD7: 0.0012694465 | AE7: 0.0024502445 | AF7: 0.0010710379 | AG7: 0
A8: 308 | C8: 0.17528803 | D8: 0.23579 | E8: 0.26626104 | F8: 0.29386772 | G8: 0.34096859 | H8: NaN | I8: NaN | J8: 0.28039695 | K8: 0.19138765 | L8: 0.11835235 | M8: NaN | N8: NaN | O8: NaN | P8: NaN | Q8: NaN | R8: NaN | S8: NaN | T8: NaN | U8: NaN | V8: NaN | W8: NaN | X8: 0.014564735 | Y8: 0.010091326 | Z8: 0.0089860789 | AA8: 0.0095446974 | AB8: 0.0061359955 | AC8: 0.0067296729 | AD8: 0.0031957106 | AE8: 0.0036834038 | AF8: 0.0003457175 | AG8: 0.0019068491
A9: 310 | C9: 0.22354671 | D9: 0.26407055 | E9: 0.27768175 | F9: 0.30311088 | G9: 0.35049781 | H9: 0.37143261 | I9: NaN | J9: NaN | K9: 0.20831155 | L9: 0.12524735 | M9: NaN | N9: NaN | O9: NaN | P9: NaN | Q9: NaN | R9: NaN | S9: NaN | T9: NaN | U9: NaN | V9: NaN | W9: NaN | X9: 0.018936251 | Y9: 0.011629865 | Z9: 0.011086899 | AA9: 0.0090885933 | AB9: 0.0068550196 | AC9: 0.0059325686 | AD9: 0.0042488596 | AE9: 0.0037596796 | AF9: 0.0013383697 | AG9: 0.0028292663
A10: 312 | C10: 0.27827599 | D10: 0.28986694 | E10: 0.2895719 | F10: 0.31896037 | G10: 0.35255566 | H10: 0.38368084 | I10: NaN | J10: NaN | K10: 0.22681511 | L10: 0.13963581 | M10: 0.091382764 | N10: NaN | O10: NaN | P10: NaN | Q10: NaN | R10: NaN | S10: NaN | T10: NaN | U10: NaN | V10: NaN | W10: NaN | X10: NaN | Y10: 0.01526705 | Z10: 0.011235648 | AA10: 0.0091108288 | AB10: 0.0075424272 | AC10: 0.0056048904 | AD10: 0.0044369813 | AE10: 0.0037234323 | AF10: 0.0024554918 | AG10: 0.0014876195
A11: 314 | C11: 0.27790763 | D11: 0.32716074 | E11: 0.3135889 | F11: 0.33077872 | G11: 0.35525426 | H11: 0.38686118 | I11: NaN | J11: NaN | K11: 0.24500525 | L11: 0.16532994 | M11: 0.10492894 | N11: NaN | O11: NaN | P11: NaN | Q11: NaN | R11: NaN | S11: NaN | T11: NaN | U11: NaN | V11: NaN | W11: NaN | X11: NaN | Y11: 0.020094734 | Z11: 0.011408965 | AA11: 0.0099137114 | AB11: 0.0081671727 | AC11: 0.0074149991 | AD11: 0.0053370233 | AE11: 0.0032314056 | AF11: 0.0022174774 | AG11: 0.0019380319
A12: 316 | C12: 0.28894241 | D12: 0.3172397 | E12: 0.33693043 | F12: 0.34219176 | G12: 0.35013235 | H12: 0.38425319 | I12: 0.36951467 | J12: NaN | K12: NaN | L12: 0.19323842 | M12: 0.11961331 | N12: 0.089835769 | O12: NaN | P12: NaN | Q12: NaN | R12: NaN | S12: NaN | T12: NaN | U12: NaN | V12: NaN | W12: NaN | X12: NaN | Y12: 0.026367825 | Z12: 0.014527362 | AA12: 0.010866436 | AB12: 0.0076106766 | AC12: 0.0098937518 | AD12: 0.0050903711 | AE12: 0.0031696047 | AF12: 0.0031813761 | AG12: 0.003014418
A13: 318 | C13: 0.34624367 | D13: 0.2847687 | E13: 0.35215663 | F13: 0.37010044 | G13: 0.36539469 | H13: 0.39059392 | I13: 0.39628053 | J13: NaN | K13: NaN | L13: 0.21059843 | M13: 0.13642004 | N13: 0.090680627 | O13: NaN | P13: NaN | Q13: NaN | R13: NaN | S13: NaN | T13: NaN | U13: NaN | V13: NaN | W13: NaN | X13: NaN | Y13: NaN | Z13: 0.011952156 | AA13: 0.0079736385 | AB13: 0.0064270899 | AC13: 0.0075618285 | AD13: 0.004537267 | AE13: 0.003750782 | AF13: 0.0017524063 | AG13: 0.0022745031
A14: 320 | C14: 0.35146623 | D14: 0.33126888 | E14: 0.35070125 | F14: 0.35286385 | G14: 0.37438643 | H14: 0.40065059 | I14: 0.38853855 | J14: NaN | K14: NaN | L14: 0.21988861 | M14: 0.15661242 | N14: 0.10387531 | O14: NaN | P14: NaN | Q14: NaN | R14: NaN | S14: NaN | T14: NaN | U14: NaN | V14: NaN | W14: NaN | X14: NaN | Y14: NaN | Z14: 0.015097826 | AA14: 0.0063408588 | AB14: 0.0044593198 | AC14: 0.0070308054 | AD14: 0.002915453 | AE14: 0.0011948411 | AF14: 0.0025767552 | AG14: 0.0040026153
A15: 322 | C15: 0.38764715 | D15: 0.39498653 | E15: 0.3888737 | F15: 0.38792325 | G15: 0.41274538 | H15: 0.42248431 | I15: 0.41240119 | J15: 0.38716805 | K15: NaN | L15: NaN | M15: 0.18082834 | N15: 0.12627699 | O15: 0.092565475 | P15: NaN | Q15: NaN | R15: NaN | S15: NaN | T15: NaN | U15: NaN | V15: NaN | W15: NaN | X15: NaN | Y15: NaN | Z15: NaN | AA15: 0.01322049 | AB15: 0.0068582658 | AC15: 0.0079335539 | AD15: 0.0089021918 | AE15: 0.0071665574 | AF15: 0.0073251147 | AG15: 0.0049163978
A16: 324 | C16: 0.38369584 | D16: 0.40061622 | E16: 0.42456868 | F16: 0.40445113 | G16: 0.42910672 | H16: 0.44145543 | I16: 0.43854532 | J16: 0.41548377 | K16: NaN | L16: NaN | M16: 0.2040233 | N16: 0.15283181 | O16: 0.10856551 | P16: NaN | Q16: NaN | R16: NaN | S16: NaN | T16: NaN | U16: NaN | V16: NaN | W16: NaN | X16: NaN | Y16: NaN | Z16: NaN | AA16: 0.014725048 | AB16: 0.0095449546 | AC16: 0.007339245 | AD16: 0.0075012306 | AE16: 0.0060197857 | AF16: 0.0060894769 | AG16: 0.0037170429
A17: 326 | C17: 0.43131663 | D17: 0.43745575 | E17: 0.45638984 | F17: 0.43620722 | G17: 0.4467382 | H17: 0.45961345 | I17: 0.45923749 | J17: 0.44243615 | K17: NaN | L17: NaN | M17: 0.2304581 | N17: 0.17763116 | O17: 0.13010494 | P17: 0.11618571 | Q17: NaN | R17: NaN | S17: NaN | T17: NaN | U17: NaN | V17: NaN | W17: NaN | X17: NaN | Y17: NaN | Z17: NaN | AA17: 0.023096111 | AB17: 0.012859302 | AC17: 0.0089556261 | AD17: 0.0091522505 | AE17: 0.0098040195 | AF17: 0.0083910913 | AG17: 0.0054357451
A18: 328 | C18: 0.47013069 | D18: 0.4579058 | E18: 0.45241909 | F18: 0.45930133 | G18: 0.45973023 | H18: 0.4686904 | I18: 0.46864051 | J18: 0.45852848 | K18: 0.39009832 | L18: NaN | M18: NaN | N18: 0.1972946 | O18: 0.1483137 | P18: 0.1133951 | Q18: NaN | R18: NaN | S18: NaN | T18: NaN | U18: NaN | V18: NaN | W18: NaN | X18: NaN | Y18: NaN | Z18: NaN | AA18: NaN | AB18: 0.013854276 | AC18: 0.0095920937 | AD18: 0.0093803 | AE18: 0.0096890512 | AF18: 0.0077654204 | AG18: 0.0060111168
A19: 330 | C19: 0.47184358 | D19: 0.4569013 | E19: 0.44628236 | F19: 0.46334609 | G19: 0.46702276 | H19: 0.47680276 | I19: 0.48220082 | J19: 0.46817351 | K19: 0.41186684 | L19: NaN | M19: NaN | N19: 0.2180304 | O19: 0.16689956 | P19: 0.12279085 | Q19: NaN | R19: NaN | S19: NaN | T19: NaN | U19: NaN | V19: NaN | W19: NaN | X19: NaN | Y19: NaN | Z19: NaN | AA19: NaN | AB19: 0.015394028 | AC19: 0.0086764916 | AD19: 0.0064712114 | AE19: 0.0047442977 | AF19: 0.0047332507 | AG19: 0.0051744889
A20: 332 | C20: 0.50447122 | D20: 0.51001375 | E20: 0.49776555 | F20: 0.48130614 | G20: 0.48430976 | H20: 0.49740692 | I20: 0.51426435 | J20: 0.48536661 | K20: 0.44790956 | L20: NaN | M20: NaN | N20: 0.2475707 | O20: 0.19492387 | P20: 0.14710794 | Q20: 0.10687155 | R20: NaN | S20: NaN | T20: NaN | U20: NaN | V20: NaN | W20: NaN | X20: NaN | Y20: NaN | Z20: NaN | AA20: NaN | AB20: NaN | AC20: 0.010875216 | AD20: 0.0072185321 | AE20: 0.0079844644 | AF20: 0.0084855921 | AG20: 0.0074294438
A21: 334 | C21: 0.53842616 | D21: 0.5496121 | E21: 0.50949498 | F21: 0.50849951 | G21: 0.49815234 | H21: 0.49823395 | I21: 0.51964197 | J21: 0.49786506 | K21: 0.48042376 | L21: 0.40556219 | M21: NaN | N21: 0.27546682 | O21: 0.21837375 | P21: 0.16469682 | Q21: 0.12456257 | R21: NaN | S21: NaN | T21: NaN | U21: NaN | V21: NaN | W21: NaN | X21: NaN | Y21: NaN | Z21: NaN | AA21: NaN | AB21: NaN | AC21: 0.015064498 | AD21: 0.006146343 | AE21: 0.0099932799 | AF21: 0.0053234224 | AG21: 0.0055600085
A22: 336 | C22: 0.56369207 | D22: 0.56487057 | E22: 0.53795394 | F22: 0.52192339 | G22: 0.53019772 | H22: 0.52749712 | I22: 0.53239045 | J22: 0.52546936 | K22: 0.50199034 | L22: 0.43503039 | M22: NaN | N22: NaN | O22: 0.24467829 | P22: 0.18884295 | Q22: 0.14741854 | R22: 0.11764445 | S22: NaN | T22: NaN | U22: NaN | V22: NaN | W22: NaN | X22: NaN | Y22: NaN | Z22: NaN | AA22: NaN | AB22: NaN | AC22: 0.019886717 | AD22: 0.013247598 | AE22: 0.005964498 | AF22: 0.0047830437 | AG22: 0.007735382
A23: 338 | C23: 0.57915483 | D23: 0.59649083 | E23: 0.55232798 | F23: 0.54167043 | G23: 0.54645903 | H23: 0.55308189 | I23: 0.55539066 | J23: 0.54963212 | K23: 0.53222015 | L23: 0.47468629 | M23: NaN | N23: NaN | O23: 0.27107938 | P23: 0.22326403 | Q23: 0.17273513 | R23: 0.13255667 | S23: NaN | T23: NaN | U23: NaN | V23: NaN | W23: NaN | X23: NaN | Y23: NaN | Z23: NaN | AA23: NaN | AB23: NaN | AC23: NaN | AD23: 0.012652939 | AE23: 0.0071751756 | AF23: 0.0066685556 | AG23: 0.0053462553
A24: 340 | C24: 0.6238305 | D24: 0.62690198 | E24: 0.57434772 | F24: 0.5703601 | G24: 0.57428559 | H24: 0.57349744 | I24: 0.5805259 | J24: 0.56574787 | K24: 0.55343486 | L24: 0.50064603 | M24: 0.42806469 | N24: NaN | O24: 0.30608009 | P24: 0.25081867 | Q24: 0.19255467 | R24: 0.15552403 | S24: NaN | T24: NaN | U24: NaN | V24: NaN | W24: NaN | X24: NaN | Y24: NaN | Z24: NaN | AA24: NaN | AB24: NaN | AC24: NaN | AD24: 0.018672978 | AE24: 0.0031033293 | AF24: 0.0069440862 | AG24: 0.0061472328
A25: 342 | C25: 0.68521936 | D25: 0.67022625 | E25: 0.62435878 | F25: 0.60815352 | G25: 0.59483018 | H25: 0.59542942 | I25: 0.59811652 | J25: 0.59832733 | K25: 0.58459245 | L25: 0.53650399 | M25: 0.46959591 | N25: NaN | O25: NaN | P25: 0.28402576 | Q25: 0.22527336 | R25: 0.18495856 | S25: 0.14479248 | T25: NaN | U25: NaN | V25: NaN | W25: NaN | X25: NaN | Y25: NaN | Z25: NaN | AA25: NaN | AB25: NaN | AC25: NaN | AD25: NaN | AE25: 0.0081521066 | AF25: 0.008901033 | AG25: 0.0099503515
A26: 344 | C26: 0.73705531 | D26: 0.70088218 | E26: 0.66500048 | F26: 0.64070223 | G26: 0.62137441 | H26: 0.61430594 | I26: 0.61190759 | J26: 0.63075216 | K26: 0.61513345 | L26: 0.57473341 | M26: 0.51280334 | N26: NaN | O26: NaN | P26: 0.32354502 | Q26: 0.2629539 | R26: 0.21781598 | S26: 0.1701234 | T26: NaN | U26: NaN | V26: NaN | W26: NaN | X26: NaN | Y26: NaN | Z26: NaN | AA26: NaN | AB26: NaN | AC26: NaN | AD26: NaN | AE26: 0.016353562 | AF26: 0.0099504813 | AG26: 0.011185315
A27: 346 | C27: 0.76761853 | D27: 0.71465326 | E27: 0.68539264 | F27: 0.66042176 | G27: 0.64867224 | H27: 0.6312972 | I27: 0.63287804 | J27: 0.65477244 | K27: 0.63614152 | L27: 0.60597624 | M27: 0.55176027 | N27: NaN | O27: NaN | P27: 0.36364019 | Q27: 0.30033423 | R27: 0.25017422 | S27: 0.19743996 | T27: 0.15428557 | U27: NaN | V27: NaN | W27: NaN | X27: NaN | Y27: NaN | Z27: NaN | AA27: NaN | AB27: NaN | AC27: NaN | AD27: NaN | AE27: 0.021104484 | AF27: 0.0085653993 | AG27: 0.0087135393
A28: 348 | C28: 0.79889452 | D28: 0.74112368 | E28: 0.71394798 | F28: 0.68119792 | G28: 0.66719624 | H28: 0.6575528 | I28: 0.66800232 | J28: 0.68189522 | K28: 0.66071234 | L28: 0.63706499 | M28: 0.59738569 | N28: 0.53960927 | O28: NaN | P28: NaN | Q28: 0.34274819 | R28: 0.28438818 | S28: 0.22968882 | T28: 0.18262761 | U28: NaN | V28: NaN | W28: NaN | X28: NaN | Y28: NaN | Z28: NaN | AA28: NaN | AB28: NaN | AC28: NaN | AD28: NaN | AE28: NaN | AF28: 0.0080940841 | AG28: 0.0069770485
A29: 350 | C29: 0.87336097 | D29: 0.79418938 | E29: 0.75360274 | F29: 0.72908471 | G29: 0.71791496 | H29: 0.6989829 | I29: 0.70950831 | J29: 0.70847193 | K29: 0.70961785 | L29: 0.67820674 | M29: 0.6509611 | N29: 0.58789326 | O29: NaN | P29: NaN | Q29: 0.38701897 | R29: 0.32853699 | S29: 0.26744811 | T29: 0.21825647 | U29: NaN | V29: NaN | W29: NaN | X29: NaN | Y29: NaN | Z29: NaN | AA29: NaN | AB29: NaN | AC29: NaN | AD29: NaN | AE29: NaN | AF29: 0.013465862 | AG29: 0.0083711789
A30: 352 | C30: 0.91344365 | D30: 0.8567009 | E30: 0.80539499 | F30: 0.77475095 | G30: 0.72837627 | H30: 0.74109027 | I30: 0.73298144 | J30: 0.74068444 | K30: 0.75405204 | L30: 0.72282207 | M30: 0.68321767 | N30: 0.6397597 | O30: NaN | P30: NaN | Q30: 0.43982502 | R30: 0.37016262 | S30: 0.31037787 | T30: 0.25118991 | U30: 0.19848371 | V30: NaN | W30: NaN | X30: NaN | Y30: NaN | Z30: NaN | AA30: NaN | AB30: NaN | AC30: NaN | AD30: NaN | AE30: NaN | AF30: NaN | AG30: 0.010028469
A31: 354 | C31: 0.99114186 | D31: 0.89748304 | E31: 0.85731655 | F31: 0.78624021 | G31: 0.78182513 | H31: 0.76380252 | I31: 0.75734142 | J31: 0.78082743 | K31: 0.78286385 | L31: 0.76189497 | M31: 0.73067804 | N31: 0.6812339 | O31: 0.62912482 | P31: NaN | Q31: NaN | R31: 0.42614967 | S31: 0.3646719 | T31: 0.29109903 | U31: 0.22990811 | V31: NaN | W31: NaN | X31: NaN | Y31: NaN | Z31: NaN | AA31: NaN | AB31: NaN | AC31: NaN | AD31: NaN | AE31: NaN | AF31: NaN | AG31: 0.010280693
A32: 356 | C32: 1.0367676 | D32: 0.9874543 | E32: 0.90467978 | F32: 0.84173153 | G32: 0.81416833 | H32: 0.8059352 | I32: 0.79255112 | J32: 0.79901489 | K32: 0.81672151 | L32: 0.80337993 | M32: 0.77143342 | N32: 0.73384946 | O32: 0.68044712 | P32: NaN | Q32: NaN | R32: 0.47875626 | S32: 0.41247885 | T32: 0.33643936 | U32: 0.26764248 | V32: 0.20399568 | W32: NaN | X32: NaN | Y32: NaN | Z32: NaN | AA32: NaN | AB32: NaN | AC32: NaN | AD32: NaN | AE32: NaN | AF32: NaN | AG32: 0.016110081
A33: 358 | C33: 1.1174049 | D33: 1.0527989 | E33: 0.96937848 | F33: 0.89433056 | G33: 0.84432076 | H33: 0.83784711 | I33: 0.82149193 | J33: 0.83652252 | K33: 0.85208177 | L33: 0.84025537 | M33: 0.81340115 | N33: 0.78515111 | O33: 0.72593199 | P33: NaN | Q33: NaN | R33: 0.52412954 | S33: 0.45777937 | T33: 0.38518425 | U33: 0.3076748 | V33: 0.23316123 | W33: NaN | X33: NaN | Y33: NaN | Z33: NaN | AA33: NaN | AB33: NaN | AC33: NaN | AD33: NaN | AE33: NaN | AF33: NaN | AG33: NaN
A34: 360 | C34: 1.2022892 | D34: 1.100222 | E34: 1.0080461 | F34: 0.93197288 | G34: 0.88635155 | H34: 0.86986268 | I34: 0.84982455 | J34: 0.86903317 | K34: 0.88529684 | L34: 0.87825046 | M34: 0.86116014 | N34: 0.82895665 | O34: 0.78150488 | P34: 0.70660891 | Q34: NaN | R34: NaN | S34: 0.50662612 | T34: 0.43277886 | U34: 0.34808626 | V34: 0.26477983 | W34: NaN | X34: NaN | Y34: NaN | Z34: NaN | AA34: NaN | AB34: NaN | AC34: NaN | AD34: NaN | AE34: NaN | AF34: NaN | AG34: NaN
A35: 362 | C35: 1.2802513 | D35: 1.1535636 | E35: 1.0479154 | F35: 0.98014863 | G35: 0.93570242 | H35: 0.90960918 | I35: 0.88709871 | J35: 0.90029302 | K35: 0.92075157 | L35: 0.91964721 | M35: 0.90956816 | N35: 0.87386035 | O35: 0.8384906 | P35: 0.76330044 | Q35: NaN | R35: NaN | S35: 0.56017783 | T35: 0.47911194 | U35: 0.3929438 | V35: 0.30114525 | W35: 0.21962461 | X35: NaN | Y35: NaN | Z35: NaN | AA35: NaN | AB35: NaN | AC35: NaN | AD35: NaN | AE35: NaN | AF35: NaN | AG35: NaN
A36: 364 | C36: 1.3691609 | D36: 1.2246455 | E36: 1.1421068 | F36: 1.0457041 | G36: 0.98198521 | H36: 0.95169897 | I36: 0.93282104 | J36: 0.955105 | K36: 0.96691714 | L36: 0.96316156 | M36: 0.9576325 | N36: 0.93257013 | O36: 0.88372571 | P36: 0.83636239 | Q36: NaN | R36: NaN | S36: 0.61547876 | T36: 0.53027519 | U36: 0.44434583 | V36: 0.34300399 | W36: 0.25512116 | X36: NaN | Y36: NaN | Z36: NaN | AA36: NaN | AB36: NaN | AC36: NaN | AD36: NaN | AE36: NaN | AF36: NaN | AG36: NaN
A37: 366 | C37: 1.4181045 | D37: 1.3290077 | E37: 1.1989587 | F37: 1.0648492 | G37: 1.0260055 | H37: 1.0008354 | I37: 0.9748543 | J37: 0.98570556 | K37: 1.0187472 | L37: 1.0119685 | M37: 1.0196832 | N37: 0.99680211 | O37: 0.94577028 | P37: 0.8891738 | Q37: 0.82791599 | R37: NaN | S37: NaN | T37: 0.58953248 | U37: 0.49007731 | V37: 0.39259439 | W37: 0.28600834 | X37: 0.19378806 | Y37: NaN | Z37: NaN | AA37: NaN | AB37: NaN | AC37: NaN | AD37: NaN | AE37: NaN | AF37: NaN | AG37: NaN
A38: 368 | C38: 1.4937541 | D38: 1.420192 | E38: 1.2697317 | F38: 1.1490167 | G38: 1.0764686 | H38: 1.0556324 | I38: 1.0296592 | J38: 1.0369302 | K38: 1.0603676 | L38: 1.0572147 | M38: 1.0730153 | N38: 1.0502784 | O38: 1.0064107 | P38: 0.95445968 | Q38: 0.88320238 | R38: NaN | S38: NaN | T38: 0.64053732 | U38: 0.54682192 | V38: 0.43707635 | W38: 0.32482352 | X38: 0.22357183 | Y38: NaN | Z38: NaN | AA38: NaN | AB38: NaN | AC38: NaN | AD38: NaN | AE38: NaN | AF38: NaN | AG38: NaN
A39: 370 | C39: 1.6710203 | D39: 1.5359519 | E39: 1.3617838 | F39: 1.2160634 | G39: 1.1468669 | H39: 1.1146987 | I39: 1.0780358 | J39: 1.0897568 | K39: 1.1125094 | L39: 1.120067 | M39: 1.1204244 | N39: 1.1095401 | O39: 1.0740519 | P39: 1.0109127 | Q39: 0.94972964 | R39: NaN | S39: NaN | T39: 0.70444267 | U39: 0.59991016 | V39: 0.48679412 | W39: 0.3646866 | X39: 0.25695808 | Y39: NaN | Z39: NaN | AA39: NaN | AB39: NaN | AC39: NaN | AD39: NaN | AE39: NaN | AF39: NaN | AG39: NaN
A40: 372 | C40: 1.7806154 | D40: 1.6351183 | E40: 1.4501937 | F40: 1.3009442 | G40: 1.2327937 | H40: 1.183841 | I40: 1.1468784 | J40: 1.1391105 | K40: 1.1824666 | L40: 1.1866181 | M40: 1.1965816 | N40: 1.1898765 | O40: 1.15377 | P40: 1.0877321 | Q40: 1.025622 | R40: 0.9469866 | S40: NaN | T40: NaN | U40: 0.6596858 | V40: 0.54273518 | W40: 0.41569361 | X40: 0.30049998 | Y40: 0.20426877 | Z40: NaN | AA40: NaN | AB40: NaN | AC40: NaN | AD40: NaN | AE40: NaN | AF40: NaN | AG40: NaN
...

Sheet DOC (mg L^-1)
A1: Spring_freshet_t0 | B1: Spring_freshet_t10 | C1: Spring_freshet_t10_dark_control | D1: Late_summer_t0 | E1: Late_summer_t7 | F1: Late_summer_t7_dark_control | G1: Under_ice_t0 | H1: Under_ice_t6 | I1: Under_ice_t6_dark_control
A2: 10.8 | B2: 9.23 | C2: 10.62 | D2: 5.72 | E2: 5.41 | F2: 5.48 | G2: 2.72 | H2: 2.36 | I2: 2.78

Sheet Lignin
B1: Spring_freshet_t0 | C1: Spring_freshet_t10 | D1: Late_summer_t0 | E1: Late_summer_t7 | F1: Under_ice_t0 | G1: Under_ice_t6
A2: Σ8 (µg L-1) | B2: 47.4 | C2: 20.6 | D2: 6 | E2: 2.8 | F2: 2.7 | G2: 2.6
A3: Λ8 (mg (100 mg OC)-1) | B3: 0.44 | C3: 0.22 | D3: 0.11 | E3: 0.05 | F3: 0.1 | G3: 0.11
A4: S:V | B4: 0.28 | C4: 0.18 | D4: 0.25 | E4: 0.22 | F4: 0.31 | G4: -
A5: C:V | B5: 0.02 | C5: 0.13 | D5: 0.04 | E5: 0.38 | F5: 0.58 | G5: -
A6: P:V | B6: 0.62 | C6: 0.69 | D6: 1.75 | E6: 3.1 | F6: 3.63 | G6: -
A7: (Ad:Al)v | B7: 2.32 | C7: 3.12 | D7: 2.1 | E7: 2.31 | F7: 1.7 | G7: -
A8: (Ad:Al)s | B8: 1.17 | C8: 0.91 | D8: 0.95 | E8: 0.88 | F8: 0.9 | G8: -

Sheet FT ICR-MS 
B1: Spring_freshet_t0 | C1: Spring_freshet_t10 | D1: Late_summer_t0 | E1: Late_summer_t7 | F1: Under_ice_t0 | G1: Under_ice_t6
A2: Mass (Da) | B2: 502.9 | C2: 481.4 | D2: 487.7 | E2: 473.7 | F2: 478.3 | G2: 461.1
A3: Number of molecular formulae | B3: 10599 | C3: 9893 | D3: 9854 | E3: 9037 | F3: 10615 | G3: 8962
A4: H:C | B4: 1.05 | C4: 1.1 | D4: 1.04 | E4: 1.1 | F4: 1.09 | G4: 1.16
A5: O:C | B5: 0.51 | C5: 0.51 | D5: 0.51 | E5: 0.52 | F5: 0.49 | G5: 0.49
A6: AImod | B6: 0.34 | C6: 0.29 | D6: 0.33 | E6: 0.28 | F6: 0.3 | G6: 0.26
A7: Condensed aromatic (%RA) | B7: 3.5 | C7: 2.2 | D7: 2.8 | E7: 1.5 | F7: 1.1 | G7: 0.6
A8: Polyphenolic (%RA) | B8: 16.2 | C8: 11.2 | D8: 14.8 | E8: 9.2 | F8: 10 | G8: 5.9
A9: HUP, low O (%RA) | B9: 33 | C9: 32.5 | D9: 32.4 | E9: 31.1 | F9: 38.7 | G9: 37.8
A10: HUP, high O (%RA) | B10: 42.6 | C10: 47.1 | D10: 46.7 | E10: 52.5 | F10: 46.1 | G10: 48.3
A11: Aliphatic (%RA) | B11: 4.7 | C11: 7 | D11: 3.3 | E11: 5.8 | F11: 4.1 | G11: 7.5
